Workbook

Sheet Plan
B1: Plantilla de estimacion y seguimiento Scrum | V1: Versión | W1: 2.14 | X1: 2.14 Scrum
B2: Fase | C2: Actividad | D2: Minutos Estimados | M2: Minutos Reales
D4: Líder/SM | E4: Product Owner | F4: Planif. | G4: Desarrollo | H4: Cambios | I4: Calidad | J4: Total | K4: Acumulado | L4: Semana Estimada | M4: Líder/SM | N4: Product Owner | O4: Planif. | P4: Desarrollo | Q4: Cambios | R4: Calidad | S4: Total | T4: Acumulado | U4: Semana Fin | V4: Estado | Y4: Asignación de roles
B5: Lanzamiento | C5: Asignar equipos y roles | D5: 10 | E5: 10 | F5: 10 | G5: 10 | H5: 10 | I5: 10 | J5: =IF(SUM(D5:I5)=0,"",SUM(D5:I5)) -> 60 | K5: =SUM($J$5:J5) -> 60 | L5: 1 | M5: 10 | N5: 10 | O5: 10 | P5: 10 | Q5: 10 | R5: 10 | S5: =SUM(M5:R5) -> 60 | T5: =SUM($S$5:S5) -> 60 | U5: 1 | V5: Completada | Y5: Rol | Z5: Persona asignada | AA5: Columnas esfuerzo
B6: Lanzamiento | C6: Definir proceso de reuniones | D6: 20 | E6: 20 | F6: 20 | G6: 20 | H6: 20 | I6: 20 | J6: =IF(SUM(D6:I6)=0,"",SUM(D6:I6)) -> 120 | K6: =SUM($J$5:J6) -> 180 | L6: 1 | M6: 20 | N6: 20 | O6: 20 | P6: 20 | Q6: 20 | R6: 20 | S6: =SUM(M6:R6) -> 120 | T6: =SUM($S$5:S6) -> 180 | U6: 1 | V6: Completada | Y6: Líder / Scrum Master | Z6: Santi | AA6: Estim. D / Real M
B7: Lanzamiento | C7: Realizar Estándar de Documentación | E7: 20 | J7: =IF(SUM(D7:I7)=0,"",SUM(D7:I7)) -> 20 | K7: =SUM($J$5:J7) -> 200 | L7: 1 | N7: 30 | R7: 20 | S7: =SUM(M7:R7) -> 50 | T7: =SUM($S$5:S7) -> 230 | U7: 2 | V7: Completada | Y7: Product Owner | Z7: Joaquin | AA7: Estim. E / Real N
B8: Lanzamiento | C8: Realizar Estándar de Agendas | D8: 10 | E8: 10 | F8: 10 | G8: 10 | H8: 10 | I8: 10 | J8: =IF(SUM(D8:I8)=0,"",SUM(D8:I8)) -> 60 | K8: =SUM($J$5:J8) -> 260 | L8: 1 | M8: 20 | N8: 20 | O8: 15 | P8: 15 | Q8: 15 | R8: 10 | S8: =SUM(M8:R8) -> 95 | T8: =SUM($S$5:S8) -> 325 | U8: 1 | V8: Completada | Y8: Planificación | Z8: Pablo | AA8: Estim. F / Real O
B9: Lanzamiento | C9: Realizar Estándar de Actas | D9: 20 | J9: =IF(SUM(D9:I9)=0,"",SUM(D9:I9)) -> 20 | K9: =SUM($J$5:J9) -> 280 | L9: 1 | M9: 20 | S9: =SUM(M9:R9) -> 20 | T9: =SUM($S$5:S9) -> 345 | U9: 3 | V9: Completada | Y9: Desarrollo | Z9: Victor | AA9: Estim. G / Real P
B10: Lanzamiento | C10: Definir Ciclo de Vida a aplicar (actividades) | D10: 10 | E10: 10 | F10: 10 | G10: 10 | H10: 10 | I10: 10 | J10: =IF(SUM(D10:I10)=0,"",SUM(D10:I10)) -> 60 | K10: =SUM($J$5:J10) -> 340 | L10: 1 | M10: 15 | N10: 15 | O10: 15 | P10: 15 | Q10: 15 | R10: 10 | S10: =SUM(M10:R10) -> 85 | T10: =SUM($S$5:S10) -> 430 | U10: 1 | V10: Completada | Y10: Cambios | Z10: Carlos | AA10: Estim. H / Real Q
B11: Lanzamiento | C11: Definir outputs y plantillas del CV | D11: 15 | J11: =IF(SUM(D11:I11)=0,"",SUM(D11:I11)) -> 15 | K11: =SUM($J$5:J11) -> 355 | L11: 1 | M11: 20 | S11: =SUM(M11:R11) -> 20 | T11: =SUM($S$5:S11) -> 450 | U11: 3 | V11: Completada | Y11: Calidad | Z11: Miguel | AA11: Estim. I / Real R
B12: Lanzamiento | C12: Definir Entorno de Desarrollo | D12: 15 | E12: 15 | F12: 15 | G12: 15 | H12: 15 | I12: 15 | J12: =IF(SUM(D12:I12)=0,"",SUM(D12:I12)) -> 90 | K12: =SUM($J$5:J12) -> 445 | L12: 1 | M12: 20 | N12: 20 | O12: 20 | P12: 20 | Q12: 10 | R12: 15 | S12: =SUM(M12:R12) -> 105 | T12: =SUM($S$5:S12) -> 555 | U12: 1 | V12: Completada | Y12: Celdas amarillas: persona asignada. El orden de columnas es el de D4:I4 y M4:R4. | Z12: Estim. U / Real V
B13: Lanzamiento | C13: Configurar Entorno de Desarrollo | D13: 45 | E13: 45 | F13: 45 | G13: 45 | H13: 45 | I13: 45 | J13: =IF(SUM(D13:I13)=0,"",SUM(D13:I13)) -> 270 | K13: =SUM($J$5:J13) -> 715 | L13: 1 | M13: 150 | S13: =SUM(M13:R13) -> 150 | T13: =SUM($S$5:S13) -> 705 | U13: 2 | V13: Completada
B14: Lanzamiento | C14: Definir Estándar de Codificación | D14: 45 | E14: 45 | F14: 45 | G14: 45 | H14: 45 | I14: 45 | J14: =IF(SUM(D14:I14)=0,"",SUM(D14:I14)) -> 270 | K14: =SUM($J$5:J14) -> 985 | L14: 1 | M14: 15 | N14: 15 | O14: 15 | P14: 15 | Q14: 10 | R14: 10 | S14: =SUM(M14:R14) -> 80 | T14: =SUM($S$5:S14) -> 785 | U14: 2 | V14: Completada | Y14: Esfuerzo Sprint1 | Z14: =6*43 -> 258 | AA14: Horas
B15: Lanzamiento | C15: Introducir datos de Planificación/Monitorización S1 (esfuerzo real / semana) | D15: 5 | E15: 5 | F15: 5 | G15: 5 | H15: 5 | I15: 5 | J15: =IF(SUM(D15:I15)=0,"",SUM(D15:I15)) -> 30 | K15: =SUM($J$5:J15) -> 1015 | L15: 1 | M15: 5 | N15: 5 | O15: 5 | P15: 5 | Q15: 5 | R15: 5 | S15: =SUM(M15:R15) -> 30 | T15: =SUM($S$5:S15) -> 815 | U15: 1 | V15: Completada | Y15: M&M (10%) | Z15: 30 | AA15: Minutos
J16: =IF(SUM(D16:I16)=0,"",SUM(D16:I16))
J17: =IF(SUM(D17:I17)=0,"",SUM(D17:I17))
J18: =IF(SUM(D18:I18)=0,"",SUM(D18:I18))
B19: Requisitos | C19: Obtener Historias de Usuario (US) | D19: 25 | E19: 25 | F19: 25 | G19: 25 | J19: =IF(SUM(D19:I19)=0,"",SUM(D19:I19)) -> 100 | K19: =SUM($J$5:J19) -> 1115 | L19: 2 | M19: 30 | N19: 30 | O19: 30 | P19: 30 | S19: =SUM(M19:R19) -> 120 | T19: =SUM($S$5:S19) -> 935 | U19: 3 | V19: Completada | Y19: Total Roles
B20: Requisitos | C20: Describir las US según plantilla (Como/Quiero/Para + criterios de aceptación) | D20: 5 | E20: 5 | F20: 5 | G20: 5 | J20: =IF(SUM(D20:I20)=0,"",SUM(D20:I20)) -> 20 | K20: =SUM($J$5:J20) -> 1135 | L20: 3 | M20: 5 | N20: 5 | O20: 5 | P20: 5 | S20: =SUM(M20:R20) -> 20 | T20: =SUM($S$5:S20) -> 955 | U20: 3 | V20: Completada | Y20: Rol | Z20: Minutos Estimados | AA20: Horas Estimadas | AB20: Minutos Reales | AC20: Horas Reales
B21: Requisitos | C21: Completar campos de US para puntos de función | E21: 120 | G21: 120 | J21: =IF(SUM(D21:I21)=0,"",SUM(D21:I21)) -> 240 | K21: =SUM($J$5:J21) -> 1375 | L21: 3 | N21: 45 | P21: 180 | S21: =SUM(M21:R21) -> 225 | T21: =SUM($S$5:S21) -> 1180 | U21: 4 | V21: Completada | Y21: Líder / Scrum Master | Z21: =SUM(D:D) -> 1980 | AA21: =Z21/60 -> 33 | AB21: =SUM(M:M) -> 590 | AC21: =AB21/60 -> 9.8333333
B22: Requisitos | C22: Elaborar Product Backlog priorizado | D22: 10 | E22: 10 | F22: 10 | G22: 10 | J22: =IF(SUM(D22:I22)=0,"",SUM(D22:I22)) -> 40 | K22: =SUM($J$5:J22) -> 1415 | L22: 3 | M22: 10 | N22: 10 | O22: 10 | P22: 10 | S22: =SUM(M22:R22) -> 40 | T22: =SUM($S$5:S22) -> 1220 | U22: 3 | V22: Completada | Y22: Product Owner | Z22: =SUM(E:E) -> 1970 | AA22: =Z22/60 -> 32.833333 | AB22: =SUM(N:N) -> 675 | AC22: =AB22/60 -> 11.25
B23: Requisitos | C23: Inspeccionar las US y criterios de aceptacion (Q) | D23: 30 | E23: 30 | F23: 30 | G23: 30 | J23: =IF(SUM(D23:I23)=0,"",SUM(D23:I23)) -> 120 | K23: =SUM($J$5:J23) -> 1535 | L23: 3 | M23: 60 | N23: 60 | O23: 60 | P23: 60 | S23: =SUM(M23:R23) -> 240 | T23: =SUM($S$5:S23) -> 1460 | U23: 4 | V23: Completada | Y23: Planificación | Z23: =SUM(F:F) -> 1815 | AA23: =Z23/60 -> 30.25 | AB23: =SUM(O:O) -> 505 | AC23: =AB23/60 -> 8.4166667
B24: Requisitos | C24: Poner en línea base las US (GCS) | D24: 5 | E24: 5 | F24: 5 | G24: 5 | J24: =IF(SUM(D24:I24)=0,"",SUM(D24:I24)) -> 20 | K24: =SUM($J$5:J24) -> 1555 | L24: 3 | M24: 5 | N24: 5 | O24: 5 | P24: 5 | S24: =SUM(M24:R24) -> 20 | T24: =SUM($S$5:S24) -> 1480 | U24: 4 | V24: Completada | Y24: Desarrollo | Z24: =SUM(G:G) -> 2085 | AA24: =Z24/60 -> 34.75 | AB24: =SUM(P:P) -> 1040 | AC24: =AB24/60 -> 17.333333
B25: Requisitos | C25: Introducir datos de Planificación/Monitorización(esfuerzo real / semana) S3 | E25: 180 | J25: =IF(SUM(D25:I25)=0,"",SUM(D25:I25)) -> 180 | K25: =SUM($J$5:J25) -> 1735 | L25: 3 | N25: 120 | P25: 120 | S25: =SUM(M25:R25) -> 240 | T25: =SUM($S$5:S25) -> 1720 | U25: 5 | V25: Completada | Y25: Cambios | Z25: =SUM(H:H) -> 160 | AA25: =Z25/60 -> 2.6666667 | AB25: =SUM(Q:Q) -> 85 | AC25: =AB25/60 -> 1.4166667
B26: Requisitos | C26: Registrar datos de calidad S3 | E26: 10 | F26: 10 | G26: 10 | J26: =IF(SUM(D26:I26)=0,"",SUM(D26:I26)) -> 30 | K26: =SUM($J$5:J26) -> 1765 | L26: 3 | N26: 10 | O26: 10 | P26: 10 | S26: =SUM(M26:R26) -> 30 | T26: =SUM($S$5:S26) -> 1750 | U26: 5 | V26: Completada | Y26: Calidad | Z26: =SUM(I:I) -> 160 | AA26: =Z26/60 -> 2.6666667 | AB26: =SUM(R:R) -> 100 | AC26: =AB26/60 -> 1.6666667
Y28: Total | Z28: =SUM(Z21:Z26) -> 8170 | AA28: =SUM(AA21:AA26) -> 136.16667 | AB28: =SUM(AB21:AB26) -> 2995 | AC28: =SUM(AC21:AC26) -> 49.916667
J29: =IF(SUM(D29:I29)=0,"",SUM(D29:I29))
J30: =IF(SUM(D30:I30)=0,"",SUM(D30:I30))
B31: Estrategia | C31: Estimar Puntos de Función sobre las US | D31: 10 | E31: 10 | F31: 10 | G31: 10 | J31: =IF(SUM(D31:I31)=0,"",SUM(D31:I31)) -> 40 | K31: =SUM($J$5:J31) -> 1805 | L31: 4 | M31: 10 | N31: 10 | O31: 10 | P31: 10 | S31: =SUM(M31:R31) -> 40 | T31: =SUM($S$5:S31) -> 1790 | U31: 4 | V31: Completada
B32: Estrategia | C32: Calcular esfuerzo (horas) | E32: 15 | G32: 30 | J32: =IF(SUM(D32:I32)=0,"",SUM(D32:I32)) -> 45 | K32: =SUM($J$5:J32) -> 1850 | L32: 4 | N32: 35 | P32: 30 | S32: =SUM(M32:R32) -> 65 | T32: =SUM($S$5:S32) -> 1855 | U32: 5 | V32: Completada
B33: Estrategia | C33: Establecer estrategia de desarrollo (US Sprint 1 y Sprint 2) | D33: 10 | E33: 10 | F33: 10 | G33: 10 | J33: =IF(SUM(D33:I33)=0,"",SUM(D33:I33)) -> 40 | K33: =SUM($J$5:J33) -> 1890 | L33: 4 | M33: 10 | N33: 10 | O33: 10 | P33: 10 | S33: =SUM(M33:R33) -> 40 | T33: =SUM($S$5:S33) -> 1895 | U33: 4 | V33: Completada
B34: Estrategia | C34: Elaborar documento de Estrategia | D34: 180 | J34: =IF(SUM(D34:I34)=0,"",SUM(D34:I34)) -> 180 | K34: =SUM($J$5:J34) -> 2070 | L34: 4 | M34: 60 | N34: 30 | P34: 105 | S34: =SUM(M34:R34) -> 195 | T34: =SUM($S$5:S34) -> 2090 | U34: 5 | V34: Completada
B35: Estrategia | C35: Elaborar Sprint Backlog con Sprint Goal y tareas de calidad | D35: 10 | E35: 10 | F35: 10 | G35: 10 | J35: =IF(SUM(D35:I35)=0,"",SUM(D35:I35)) -> 40 | K35: =SUM($J$5:J35) -> 2110 | L35: 4 | M35: 15 | N35: 15 | O35: 15 | P35: 15 | S35: =SUM(M35:R35) -> 60 | T35: =SUM($S$5:S35) -> 2150 | U35: 4 | V35: Completada
B36: Estrategia | C36: Inspeccionar outputs de Estrategia (Q) | F36: 180 | J36: =IF(SUM(D36:I36)=0,"",SUM(D36:I36)) -> 180 | K36: =SUM($J$5:J36) -> 2290 | L36: 4 | O36: 120 | S36: =SUM(M36:R36) -> 120 | T36: =SUM($S$5:S36) -> 2270 | U36: 6 | V36: Completada
B37: Estrategia | C37: Poner en línea base Estrategia y Sprint Backlog (GCS) | D37: 10 | E37: 10 | F37: 10 | G37: 10 | J37: =IF(SUM(D37:I37)=0,"",SUM(D37:I37)) -> 40 | K37: =SUM($J$5:J37) -> 2330 | L37: 4 | M37: 15 | N37: 15 | O37: 15 | P37: 15 | S37: =SUM(M37:R37) -> 60 | T37: =SUM($S$5:S37) -> 2330 | U37: 5 | V37: Completada
B38: Estrategia | C38: Introducir datos de Planificación/Monitorización S4 (esfuerzo real / semana) | E38: 10 | F38: 10 | G38: 10 | J38: =IF(SUM(D38:I38)=0,"",SUM(D38:I38)) -> 30 | K38: =SUM($J$5:J38) -> 2360 | L38: 4 | N38: 10 | O38: 10 | P38: 10 | S38: =SUM(M38:R38) -> 30 | T38: =SUM($S$5:S38) -> 2360 | U38: 6 | V38: Completada
B39: Estrategia | C39: Registrar datos de calidad S4 | D39: 5 | E39: 5 | F39: 5 | G39: 5 | J39: =IF(SUM(D39:I39)=0,"",SUM(D39:I39)) -> 20 | K39: =SUM($J$5:J39) -> 2380 | L39: 4 | M39: 5 | N39: 5 | O39: 5 | P39: 5 | S39: =SUM(M39:R39) -> 20 | T39: =SUM($S$5:S39) -> 2380 | U39: 4 | V39: Completada
J41: =IF(SUM(D41:I41)=0,"",SUM(D41:I41))
J42: =IF(SUM(D42:I42)=0,"",SUM(D42:I42))
B43: Planificación | C43: Realizar Plan de Gestión de Configuración (PGCS) | D43: 10 | E43: 10 | F43: 10 | G43: 10 | J43: =IF(SUM(D43:I43)=0,"",SUM(D43:I43)) -> 40 | K43: =SUM($J$5:J43) -> 2420 | L43: 5 | M43: 5 | N43: 40 | O43: 5 | P43: 35 | S43: =SUM(M43:R43) -> 85 | T43: =SUM($S$5:S43) -> 2465 | U43: 5 | V43: Completada
...

Sheet Lider SM
C2: Lista de tareas de Líder / Scrum Master | G2: IMPORTANTE
D3: Total min. reales | E3: =SUM(E6:E88) -> 590 | G3: ¡ NO EDITAR ESTA PÁGINA ! Se genera automaticamente
C5: Fase | D5: Actividad | E5: Esfuerzo (minutos reales)
C6: =IF(ISBLANK(Plan!B5),"",Plan!B5) -> Lanzamiento | D6: =IF(ISBLANK(Plan!C5),"",Plan!C5) -> Asignar equipos y roles | E6: =IF(ISBLANK(Plan!B5),"",IF(Plan!M5>0,Plan!M5,"")) -> 10
C7: =IF(ISBLANK(Plan!B6),"",Plan!B6) -> Lanzamiento | D7: =IF(ISBLANK(Plan!C6),"",Plan!C6) -> Definir proceso de reuniones | E7: =IF(ISBLANK(Plan!B6),"",IF(Plan!M6>0,Plan!M6,"")) -> 20
C8: =IF(ISBLANK(Plan!B7),"",Plan!B7) -> Lanzamiento | D8: =IF(ISBLANK(Plan!C7),"",Plan!C7) -> Realizar Estándar de Documentación | E8: =IF(ISBLANK(Plan!B7),"",IF(Plan!M7>0,Plan!M7,""))
C9: =IF(ISBLANK(Plan!B8),"",Plan!B8) -> Lanzamiento | D9: =IF(ISBLANK(Plan!C8),"",Plan!C8) -> Realizar Estándar de Agendas | E9: =IF(ISBLANK(Plan!B8),"",IF(Plan!M8>0,Plan!M8,"")) -> 20
C10: =IF(ISBLANK(Plan!B9),"",Plan!B9) -> Lanzamiento | D10: =IF(ISBLANK(Plan!C9),"",Plan!C9) -> Realizar Estándar de Actas | E10: =IF(ISBLANK(Plan!B9),"",IF(Plan!M9>0,Plan!M9,"")) -> 20
C11: =IF(ISBLANK(Plan!B10),"",Plan!B10) -> Lanzamiento | D11: =IF(ISBLANK(Plan!C10),"",Plan!C10) -> Definir Ciclo de Vida a aplicar (actividades) | E11: =IF(ISBLANK(Plan!B10),"",IF(Plan!M10>0,Plan!M10,"")) -> 15
C12: =IF(ISBLANK(Plan!B11),"",Plan!B11) -> Lanzamiento | D12: =IF(ISBLANK(Plan!C11),"",Plan!C11) -> Definir outputs y plantillas del CV | E12: =IF(ISBLANK(Plan!B11),"",IF(Plan!M11>0,Plan!M11,"")) -> 20
C13: =IF(ISBLANK(Plan!B12),"",Plan!B12) -> Lanzamiento | D13: =IF(ISBLANK(Plan!C12),"",Plan!C12) -> Definir Entorno de Desarrollo | E13: =IF(ISBLANK(Plan!B12),"",IF(Plan!M12>0,Plan!M12,"")) -> 20
C14: =IF(ISBLANK(Plan!B13),"",Plan!B13) -> Lanzamiento | D14: =IF(ISBLANK(Plan!C13),"",Plan!C13) -> Configurar Entorno de Desarrollo | E14: =IF(ISBLANK(Plan!B13),"",IF(Plan!M13>0,Plan!M13,"")) -> 150
C15: =IF(ISBLANK(Plan!B14),"",Plan!B14) -> Lanzamiento | D15: =IF(ISBLANK(Plan!C14),"",Plan!C14) -> Definir Estándar de Codificación | E15: =IF(ISBLANK(Plan!B14),"",IF(Plan!M14>0,Plan!M14,"")) -> 15
E16: =IF(ISBLANK(Plan!B15),"",IF(Plan!M15>0,Plan!M15,"")) -> 5
E17: =IF(ISBLANK(Plan!B16),"",IF(Plan!M16>0,Plan!M16,""))
C18: =IF(ISBLANK(Plan!B15),"",Plan!B15) -> Lanzamiento | D18: =IF(ISBLANK(Plan!C15),"",Plan!C15) -> Introducir datos de Planificación/Monitorización S1 (esfuerzo real / semana) | E18: =IF(ISBLANK(Plan!B17),"",IF(Plan!M17>0,Plan!M17,""))
C19: =IF(ISBLANK(Plan!B16),"",Plan!B16) | D19: =IF(ISBLANK(Plan!C16),"",Plan!C16) | E19: =IF(ISBLANK(Plan!B18),"",IF(Plan!M18>0,Plan!M18,""))
C20: =IF(ISBLANK(Plan!B17),"",Plan!B17) | D20: =IF(ISBLANK(Plan!C17),"",Plan!C17) | E20: =IF(ISBLANK(Plan!B19),"",IF(Plan!M19>0,Plan!M19,"")) -> 30
C21: =IF(ISBLANK(Plan!B18),"",Plan!B18) | D21: =IF(ISBLANK(Plan!C18),"",Plan!C18) | E21: =IF(ISBLANK(Plan!B20),"",IF(Plan!M20>0,Plan!M20,"")) -> 5
C22: =IF(ISBLANK(Plan!B19),"",Plan!B19) -> Requisitos | D22: =IF(ISBLANK(Plan!C19),"",Plan!C19) -> Obtener Historias de Usuario (US) | E22: =IF(ISBLANK(Plan!B21),"",IF(Plan!M21>0,Plan!M21,""))
C23: =IF(ISBLANK(Plan!B20),"",Plan!B20) -> Requisitos | D23: =IF(ISBLANK(Plan!C20),"",Plan!C20) -> Describir las US según plantilla (Como/Quiero/Para + criterios de aceptación) | E23: =IF(ISBLANK(Plan!B22),"",IF(Plan!M22>0,Plan!M22,"")) -> 10
C24: =IF(ISBLANK(Plan!B21),"",Plan!B21) -> Requisitos | D24: =IF(ISBLANK(Plan!C21),"",Plan!C21) -> Completar campos de US para puntos de función | E24: =IF(ISBLANK(Plan!B23),"",IF(Plan!M23>0,Plan!M23,"")) -> 60
C25: =IF(ISBLANK(Plan!B22),"",Plan!B22) -> Requisitos | D25: =IF(ISBLANK(Plan!C22),"",Plan!C22) -> Elaborar Product Backlog priorizado | E25: =IF(ISBLANK(Plan!B24),"",IF(Plan!M24>0,Plan!M24,"")) -> 5
C26: =IF(ISBLANK(Plan!B23),"",Plan!B23) -> Requisitos | D26: =IF(ISBLANK(Plan!C23),"",Plan!C23) -> Inspeccionar las US y criterios de aceptacion (Q) | E26: =IF(ISBLANK(Plan!B25),"",IF(Plan!M25>0,Plan!M25,""))
C27: =IF(ISBLANK(Plan!B24),"",Plan!B24) -> Requisitos | D27: =IF(ISBLANK(Plan!C24),"",Plan!C24) -> Poner en línea base las US (GCS) | E27: =IF(ISBLANK(Plan!B26),"",IF(Plan!M26>0,Plan!M26,""))
C28: =IF(ISBLANK(Plan!B25),"",Plan!B25) -> Requisitos | D28: =IF(ISBLANK(Plan!C25),"",Plan!C25) -> Introducir datos de Planificación/Monitorización(esfuerzo real / semana) S3 | E28: =IF(ISBLANK(Plan!B27),"",IF(Plan!M27>0,Plan!M27,""))
C29: =IF(ISBLANK(Plan!B26),"",Plan!B26) -> Requisitos | D29: =IF(ISBLANK(Plan!C26),"",Plan!C26) -> Registrar datos de calidad S3 | E29: =IF(ISBLANK(Plan!B28),"",IF(Plan!M28>0,Plan!M28,""))
... C49: =IF(ISBLANK(Plan!B46),"",Plan!B46) -> Planificación | D49: =IF(ISBLANK(Plan!C46),"",Plan!C46) -> Realizar Diagrama de Gantt del Sprint 1 | E49: =IF(ISBLANK(Plan!B48),"",IF(Plan!M48>0,Plan!M48,"")) -> 5
C50: =IF(ISBLANK(Plan!#REF!),"",Plan!#REF!) -> #REF! | D50: =IF(ISBLANK(Plan!#REF!),"",Plan!#REF!) -> #REF! | E50: =IF(ISBLANK(Plan!B49),"",IF(Plan!M49>0,Plan!M49,"")) -> 30
C51: =IF(ISBLANK(Plan!B47),"",Plan!B47) -> Planificación | D51: =IF(ISBLANK(Plan!C47),"",Plan!C47) -> Inspeccionar planes (Q) y poner en línea base (GCS) | E51: =IF(ISBLANK(Plan!B50),"",IF(Plan!M50>0,Plan!M50,""))
C52: =IF(ISBLANK(Plan!B48),"",Plan!B48) -> Planificación | D52: =IF(ISBLANK(Plan!C48),"",Plan!C48) -> Introducir datos de Planificación/Monitorización S5 (esfuerzo real / semana) | E52: =IF(ISBLANK(Plan!B51),"",IF(Plan!M51>0,Plan!M51,""))
C53: =IF(ISBLANK(Plan!B49),"",Plan!B49) -> Planificación | D53: =IF(ISBLANK(Plan!C49),"",Plan!C49) -> Registrar datos de calidad S5: revisiones, pruebas y defectos | E53: =IF(ISBLANK(Plan!B52),"",IF(Plan!M52>0,Plan!M52,"")) -> 5
C54: =IF(ISBLANK(Plan!B50),"",Plan!B50) | D54: =IF(ISBLANK(Plan!C50),"",Plan!C50) | E54: =IF(ISBLANK(Plan!B53),"",IF(Plan!M53>0,Plan!M53,""))
C55: =IF(ISBLANK(Plan!B51),"",Plan!B51) | D55: =IF(ISBLANK(Plan!C51),"",Plan!C51) | E55: =IF(ISBLANK(Plan!B54),"",IF(Plan!M54>0,Plan!M54,""))
C56: =IF(ISBLANK(Plan!B52),"",Plan!B52) -> Diseño | D56: =IF(ISBLANK(Plan!C52),"",Plan!C52) -> Realizar diagramas de Casos de Uso | E56: =IF(ISBLANK(Plan!B55),"",IF(Plan!M55>0,Plan!M55,"")) -> 5
C57: =IF(ISBLANK(Plan!B53),"",Plan!B53) -> Diseño | D57: =IF(ISBLANK(Plan!C53),"",Plan!C53) -> Realizar modelo Entidad/Relación y BBDD | E57: =IF(ISBLANK(Plan!B56),"",IF(Plan!M56>0,Plan!M56,"")) -> 10
C58: =IF(ISBLANK(Plan!B54),"",Plan!B54) -> Diseño | D58: =IF(ISBLANK(Plan!C54),"",Plan!C54) -> Diseñar pantallas | E58: =IF(ISBLANK(Plan!B57),"",IF(Plan!M57>0,Plan!M57,""))
C59: =IF(ISBLANK(Plan!B55),"",Plan!B55) -> Diseño | D59: =IF(ISBLANK(Plan!C55),"",Plan!C55) -> Inspeccionar diseño (Q) y poner en línea base (GCS) | E59: =IF(ISBLANK(Plan!B58),"",IF(Plan!M58>0,Plan!M58,""))
C60: =IF(ISBLANK(Plan!B56),"",Plan!B56) -> Diseño | D60: =IF(ISBLANK(Plan!C56),"",Plan!C56) -> Introducir datos de Planificación/Monitorización S6 (esfuerzo real / semana, US) | E60: =IF(ISBLANK(Plan!B59),"",IF(Plan!M59>0,Plan!M59,""))
C61: =IF(ISBLANK(Plan!B57),"",Plan!B57) | D61: =IF(ISBLANK(Plan!C57),"",Plan!C57) | E61: =IF(ISBLANK(Plan!B60),"",IF(Plan!M60>0,Plan!M60,""))
...

Sheet Producto Owner
C2: Lista de tareas de Product Owner | G2: IMPORTANTE
D3: Total min. reales | E3: =SUM(E6:E88) -> 675 | G3: ¡ NO EDITAR ESTA PÁGINA ! Se genera automaticamente
C5: Fase | D5: Actividad | E5: Esfuerzo (minutos reales)
C6: =IF(ISBLANK(Plan!B5),"",Plan!B5) -> Lanzamiento | D6: =IF(ISBLANK(Plan!C5),"",Plan!C5) -> Asignar equipos y roles | E6: =IF(ISBLANK(Plan!B5),"",IF(Plan!N5>0,Plan!N5,"")) -> 10
C7: =IF(ISBLANK(Plan!B6),"",Plan!B6) -> Lanzamiento | D7: =IF(ISBLANK(Plan!C6),"",Plan!C6) -> Definir proceso de reuniones | E7: =IF(ISBLANK(Plan!B6),"",IF(Plan!N6>0,Plan!N6,"")) -> 20
C8: =IF(ISBLANK(Plan!B7),"",Plan!B7) -> Lanzamiento | D8: =IF(ISBLANK(Plan!C7),"",Plan!C7) -> Realizar Estándar de Documentación | E8: =IF(ISBLANK(Plan!B7),"",IF(Plan!N7>0,Plan!N7,"")) -> 30
C9: =IF(ISBLANK(Plan!B8),"",Plan!B8) -> Lanzamiento | D9: =IF(ISBLANK(Plan!C8),"",Plan!C8) -> Realizar Estándar de Agendas | E9: =IF(ISBLANK(Plan!B8),"",IF(Plan!N8>0,Plan!N8,"")) -> 20
C10: =IF(ISBLANK(Plan!B9),"",Plan!B9) -> Lanzamiento | D10: =IF(ISBLANK(Plan!C9),"",Plan!C9) -> Realizar Estándar de Actas | E10: =IF(ISBLANK(Plan!B9),"",IF(Plan!N9>0,Plan!N9,""))
C11: =IF(ISBLANK(Plan!B10),"",Plan!B10) -> Lanzamiento | D11: =IF(ISBLANK(Plan!C10),"",Plan!C10) -> Definir Ciclo de Vida a aplicar (actividades) | E11: =IF(ISBLANK(Plan!B10),"",IF(Plan!N10>0,Plan!N10,"")) -> 15
C12: =IF(ISBLANK(Plan!B11),"",Plan!B11) -> Lanzamiento | D12: =IF(ISBLANK(Plan!C11),"",Plan!C11) -> Definir outputs y plantillas del CV | E12: =IF(ISBLANK(Plan!B11),"",IF(Plan!N11>0,Plan!N11,""))
C13: =IF(ISBLANK(Plan!B12),"",Plan!B12) -> Lanzamiento | D13: =IF(ISBLANK(Plan!C12),"",Plan!C12) -> Definir Entorno de Desarrollo | E13: =IF(ISBLANK(Plan!B12),"",IF(Plan!N12>0,Plan!N12,"")) -> 20
C14: =IF(ISBLANK(Plan!B13),"",Plan!B13) -> Lanzamiento | D14: =IF(ISBLANK(Plan!C13),"",Plan!C13) -> Configurar Entorno de Desarrollo | E14: =IF(ISBLANK(Plan!B13),"",IF(Plan!N13>0,Plan!N13,""))
C15: =IF(ISBLANK(Plan!B14),"",Plan!B14) -> Lanzamiento | D15: =IF(ISBLANK(Plan!C14),"",Plan!C14) -> Definir Estándar de Codificación | E15: =IF(ISBLANK(Plan!B14),"",IF(Plan!N14>0,Plan!N14,"")) -> 15
E16: =IF(ISBLANK(Plan!B15),"",IF(Plan!N15>0,Plan!N15,"")) -> 5
E17: =IF(ISBLANK(Plan!B16),"",IF(Plan!N16>0,Plan!N16,""))
C18: =IF(ISBLANK(Plan!B15),"",Plan!B15) -> Lanzamiento | D18: =IF(ISBLANK(Plan!C15),"",Plan!C15) -> Introducir datos de Planificación/Monitorización S1 (esfuerzo real / semana) | E18: =IF(ISBLANK(Plan!B17),"",IF(Plan!N17>0,Plan!N17,""))
C19: =IF(ISBLANK(Plan!B16),"",Plan!B16) | D19: =IF(ISBLANK(Plan!C16),"",Plan!C16) | E19: =IF(ISBLANK(Plan!B18),"",IF(Plan!N18>0,Plan!N18,""))
C20: =IF(ISBLANK(Plan!B17),"",Plan!B17) | D20: =IF(ISBLANK(Plan!C17),"",Plan!C17) | E20: =IF(ISBLANK(Plan!B19),"",IF(Plan!N19>0,Plan!N19,"")) -> 30
C21: =IF(ISBLANK(Plan!B18),"",Plan!B18) | D21: =IF(ISBLANK(Plan!C18),"",Plan!C18) | E21: =IF(ISBLANK(Plan!B20),"",IF(Plan!N20>0,Plan!N20,"")) -> 5
C22: =IF(ISBLANK(Plan!B19),"",Plan!B19) -> Requisitos | D22: =IF(ISBLANK(Plan!C19),"",Plan!C19) -> Obtener Historias de Usuario (US) | E22: =IF(ISBLANK(Plan!B21),"",IF(Plan!N21>0,Plan!N21,"")) -> 45
C23: =IF(ISBLANK(Plan!B20),"",Plan!B20) -> Requisitos | D23: =IF(ISBLANK(Plan!C20),"",Plan!C20) -> Describir las US según plantilla (Como/Quiero/Para + criterios de aceptación) | E23: =IF(ISBLANK(Plan!B22),"",IF(Plan!N22>0,Plan!N22,"")) -> 10
C24: =IF(ISBLANK(Plan!B21),"",Plan!B21) -> Requisitos | D24: =IF(ISBLANK(Plan!C21),"",Plan!C21) -> Completar campos de US para puntos de función | E24: =IF(ISBLANK(Plan!B23),"",IF(Plan!N23>0,Plan!N23,"")) -> 60
C25: =IF(ISBLANK(Plan!B22),"",Plan!B22) -> Requisitos | D25: =IF(ISBLANK(Plan!C22),"",Plan!C22) -> Elaborar Product Backlog priorizado | E25: =IF(ISBLANK(Plan!B24),"",IF(Plan!N24>0,Plan!N24,"")) -> 5
C26: =IF(ISBLANK(Plan!B23),"",Plan!B23) -> Requisitos | D26: =IF(ISBLANK(Plan!C23),"",Plan!C23) -> Inspeccionar las US y criterios de aceptacion (Q) | E26: =IF(ISBLANK(Plan!B25),"",IF(Plan!N25>0,Plan!N25,"")) -> 120
C27: =IF(ISBLANK(Plan!B24),"",Plan!B24) -> Requisitos | D27: =IF(ISBLANK(Plan!C24),"",Plan!C24) -> Poner en línea base las US (GCS) | E27: =IF(ISBLANK(Plan!B26),"",IF(Plan!N26>0,Plan!N26,"")) -> 10
C28: =IF(ISBLANK(Plan!B25),"",Plan!B25) -> Requisitos | D28: =IF(ISBLANK(Plan!C25),"",Plan!C25) -> Introducir datos de Planificación/Monitorización(esfuerzo real / semana) S3 | E28: =IF(ISBLANK(Plan!B27),"",IF(Plan!N27>0,Plan!N27,""))
C29: =IF(ISBLANK(Plan!B26),"",Plan!B26) -> Requisitos | D29: =IF(ISBLANK(Plan!C26),"",Plan!C26) -> Registrar datos de calidad S3 | E29: =IF(ISBLANK(Plan!B28),"",IF(Plan!N28>0,Plan!N28,""))
... C49: =IF(ISBLANK(Plan!B46),"",Plan!B46) -> Planificación | D49: =IF(ISBLANK(Plan!C46),"",Plan!C46) -> Realizar Diagrama de Gantt del Sprint 1 | E49: =IF(ISBLANK(Plan!B48),"",IF(Plan!N48>0,Plan!N48,"")) -> 5
C50: =IF(ISBLANK(Plan!#REF!),"",Plan!#REF!) -> #REF! | D50: =IF(ISBLANK(Plan!#REF!),"",Plan!#REF!) -> #REF! | E50: =IF(ISBLANK(Plan!B49),"",IF(Plan!N49>0,Plan!N49,"")) -> 20
C51: =IF(ISBLANK(Plan!B47),"",Plan!B47) -> Planificación | D51: =IF(ISBLANK(Plan!C47),"",Plan!C47) -> Inspeccionar planes (Q) y poner en línea base (GCS) | E51: =IF(ISBLANK(Plan!B50),"",IF(Plan!N50>0,Plan!N50,""))
C52: =IF(ISBLANK(Plan!B48),"",Plan!B48) -> Planificación | D52: =IF(ISBLANK(Plan!C48),"",Plan!C48) -> Introducir datos de Planificación/Monitorización S5 (esfuerzo real / semana) | E52: =IF(ISBLANK(Plan!B51),"",IF(Plan!N51>0,Plan!N51,""))
C53: =IF(ISBLANK(Plan!B49),"",Plan!B49) -> Planificación | D53: =IF(ISBLANK(Plan!C49),"",Plan!C49) -> Registrar datos de calidad S5: revisiones, pruebas y defectos | E53: =IF(ISBLANK(Plan!B52),"",IF(Plan!N52>0,Plan!N52,"")) -> 15
C54: =IF(ISBLANK(Plan!B50),"",Plan!B50) | D54: =IF(ISBLANK(Plan!C50),"",Plan!C50) | E54: =IF(ISBLANK(Plan!B53),"",IF(Plan!N53>0,Plan!N53,""))
C55: =IF(ISBLANK(Plan!B51),"",Plan!B51) | D55: =IF(ISBLANK(Plan!C51),"",Plan!C51) | E55: =IF(ISBLANK(Plan!B54),"",IF(Plan!N54>0,Plan!N54,""))
C56: =IF(ISBLANK(Plan!B52),"",Plan!B52) -> Diseño | D56: =IF(ISBLANK(Plan!C52),"",Plan!C52) -> Realizar diagramas de Casos de Uso | E56: =IF(ISBLANK(Plan!B55),"",IF(Plan!N55>0,Plan!N55,"")) -> 5
C57: =IF(ISBLANK(Plan!B53),"",Plan!B53) -> Diseño | D57: =IF(ISBLANK(Plan!C53),"",Plan!C53) -> Realizar modelo Entidad/Relación y BBDD | E57: =IF(ISBLANK(Plan!B56),"",IF(Plan!N56>0,Plan!N56,"")) -> 20
C58: =IF(ISBLANK(Plan!B54),"",Plan!B54) -> Diseño | D58: =IF(ISBLANK(Plan!C54),"",Plan!C54) -> Diseñar pantallas | E58: =IF(ISBLANK(Plan!B57),"",IF(Plan!N57>0,Plan!N57,""))
C59: =IF(ISBLANK(Plan!B55),"",Plan!B55) -> Diseño | D59: =IF(ISBLANK(Plan!C55),"",Plan!C55) -> Inspeccionar diseño (Q) y poner en línea base (GCS) | E59: =IF(ISBLANK(Plan!B58),"",IF(Plan!N58>0,Plan!N58,""))
C60: =IF(ISBLANK(Plan!B56),"",Plan!B56) -> Diseño | D60: =IF(ISBLANK(Plan!C56),"",Plan!C56) -> Introducir datos de Planificación/Monitorización S6 (esfuerzo real / semana, US) | E60: =IF(ISBLANK(Plan!B59),"",IF(Plan!N59>0,Plan!N59,""))
C61: =IF(ISBLANK(Plan!B57),"",Plan!B57) | D61: =IF(ISBLANK(Plan!C57),"",Plan!C57) | E61: =IF(ISBLANK(Plan!B60),"",IF(Plan!N60>0,Plan!N60,""))
...

Sheet Planificacion
C2: Lista de tareas de Planificación | G2: IMPORTANTE
D3: Total min. reales | E3: =SUM(E6:E88) -> 505 | G3: ¡ NO EDITAR ESTA PÁGINA ! Se genera automaticamente
C5: Fase | D5: Actividad | E5: Esfuerzo (minutos reales)
C6: =IF(ISBLANK(Plan!B5),"",Plan!B5) -> Lanzamiento | D6: =IF(ISBLANK(Plan!C5),"",Plan!C5) -> Asignar equipos y roles | E6: =IF(ISBLANK(Plan!B5),"",IF(Plan!O5>0,Plan!O5,"")) -> 10
C7: =IF(ISBLANK(Plan!B6),"",Plan!B6) -> Lanzamiento | D7: =IF(ISBLANK(Plan!C6),"",Plan!C6) -> Definir proceso de reuniones | E7: =IF(ISBLANK(Plan!B6),"",IF(Plan!O6>0,Plan!O6,"")) -> 20
C8: =IF(ISBLANK(Plan!B7),"",Plan!B7) -> Lanzamiento | D8: =IF(ISBLANK(Plan!C7),"",Plan!C7) -> Realizar Estándar de Documentación | E8: =IF(ISBLANK(Plan!B7),"",IF(Plan!O7>0,Plan!O7,""))
C9: =IF(ISBLANK(Plan!B8),"",Plan!B8) -> Lanzamiento | D9: =IF(ISBLANK(Plan!C8),"",Plan!C8) -> Realizar Estándar de Agendas | E9: =IF(ISBLANK(Plan!B8),"",IF(Plan!O8>0,Plan!O8,"")) -> 15
C10: =IF(ISBLANK(Plan!B9),"",Plan!B9) -> Lanzamiento | D10: =IF(ISBLANK(Plan!C9),"",Plan!C9) -> Realizar Estándar de Actas | E10: =IF(ISBLANK(Plan!B9),"",IF(Plan!O9>0,Plan!O9,""))
C11: =IF(ISBLANK(Plan!B10),"",Plan!B10) -> Lanzamiento | D11: =IF(ISBLANK(Plan!C10),"",Plan!C10) -> Definir Ciclo de Vida a aplicar (actividades) | E11: =IF(ISBLANK(Plan!B10),"",IF(Plan!O10>0,Plan!O10,"")) -> 15
C12: =IF(ISBLANK(Plan!B11),"",Plan!B11) -> Lanzamiento | D12: =IF(ISBLANK(Plan!C11),"",Plan!C11) -> Definir outputs y plantillas del CV | E12: =IF(ISBLANK(Plan!B11),"",IF(Plan!O11>0,Plan!O11,""))
C13: =IF(ISBLANK(Plan!B12),"",Plan!B12) -> Lanzamiento | D13: =IF(ISBLANK(Plan!C12),"",Plan!C12) -> Definir Entorno de Desarrollo | E13: =IF(ISBLANK(Plan!B12),"",IF(Plan!O12>0,Plan!O12,"")) -> 20
C14: =IF(ISBLANK(Plan!B13),"",Plan!B13) -> Lanzamiento | D14: =IF(ISBLANK(Plan!C13),"",Plan!C13) -> Configurar Entorno de Desarrollo | E14: =IF(ISBLANK(Plan!B13),"",IF(Plan!O13>0,Plan!O13,""))
C15: =IF(ISBLANK(Plan!B14),"",Plan!B14) -> Lanzamiento | D15: =IF(ISBLANK(Plan!C14),"",Plan!C14) -> Definir Estándar de Codificación | E15: =IF(ISBLANK(Plan!B14),"",IF(Plan!O14>0,Plan!O14,"")) -> 15
E16: =IF(ISBLANK(Plan!B15),"",IF(Plan!O15>0,Plan!O15,"")) -> 5
E17: =IF(ISBLANK(Plan!B16),"",IF(Plan!O16>0,Plan!O16,""))
C18: =IF(ISBLANK(Plan!B15),"",Plan!B15) -> Lanzamiento | D18: =IF(ISBLANK(Plan!C15),"",Plan!C15) -> Introducir datos de Planificación/Monitorización S1 (esfuerzo real / semana) | E18: =IF(ISBLANK(Plan!B17),"",IF(Plan!O17>0,Plan!O17,""))
C19: =IF(ISBLANK(Plan!B16),"",Plan!B16) | D19: =IF(ISBLANK(Plan!C16),"",Plan!C16) | E19: =IF(ISBLANK(Plan!B18),"",IF(Plan!O18>0,Plan!O18,""))
C20: =IF(ISBLANK(Plan!B17),"",Plan!B17) | D20: =IF(ISBLANK(Plan!C17),"",Plan!C17) | E20: =IF(ISBLANK(Plan!B19),"",IF(Plan!O19>0,Plan!O19,"")) -> 30
C21: =IF(ISBLANK(Plan!B18),"",Plan!B18) | D21: =IF(ISBLANK(Plan!C18),"",Plan!C18) | E21: =IF(ISBLANK(Plan!B20),"",IF(Plan!O20>0,Plan!O20,"")) -> 5
C22: =IF(ISBLANK(Plan!B19),"",Plan!B19) -> Requisitos | D22: =IF(ISBLANK(Plan!C19),"",Plan!C19) -> Obtener Historias de Usuario (US) | E22: =IF(ISBLANK(Plan!B21),"",IF(Plan!O21>0,Plan!O21,""))
C23: =IF(ISBLANK(Plan!B20),"",Plan!B20) -> Requisitos | D23: =IF(ISBLANK(Plan!C20),"",Plan!C20) -> Describir las US según plantilla (Como/Quiero/Para + criterios de aceptación) | E23: =IF(ISBLANK(Plan!B22),"",IF(Plan!O22>0,Plan!O22,"")) -> 10
C24: =IF(ISBLANK(Plan!B21),"",Plan!B21) -> Requisitos | D24: =IF(ISBLANK(Plan!C21),"",Plan!C21) -> Completar campos de US para puntos de función | E24: =IF(ISBLANK(Plan!B23),"",IF(Plan!O23>0,Plan!O23,"")) -> 60
C25: =IF(ISBLANK(Plan!B22),"",Plan!B22) -> Requisitos | D25: =IF(ISBLANK(Plan!C22),"",Plan!C22) -> Elaborar Product Backlog priorizado | E25: =IF(ISBLANK(Plan!B24),"",IF(Plan!O24>0,Plan!O24,"")) -> 5
C26: =IF(ISBLANK(Plan!B23),"",Plan!B23) -> Requisitos | D26: =IF(ISBLANK(Plan!C23),"",Plan!C23) -> Inspeccionar las US y criterios de aceptacion (Q) | E26: =IF(ISBLANK(Plan!B25),"",IF(Plan!O25>0,Plan!O25,""))
C27: =IF(ISBLANK(Plan!B24),"",Plan!B24) -> Requisitos | D27: =IF(ISBLANK(Plan!C24),"",Plan!C24) -> Poner en línea base las US (GCS) | E27: =IF(ISBLANK(Plan!B26),"",IF(Plan!O26>0,Plan!O26,"")) -> 10
C28: =IF(ISBLANK(Plan!B25),"",Plan!B25) -> Requisitos | D28: =IF(ISBLANK(Plan!C25),"",Plan!C25) -> Introducir datos de Planificación/Monitorización(esfuerzo real / semana) S3 | E28: =IF(ISBLANK(Plan!B27),"",IF(Plan!O27>0,Plan!O27,""))
C29: =IF(ISBLANK(Plan!B26),"",Plan!B26) -> Requisitos | D29: =IF(ISBLANK(Plan!C26),"",Plan!C26) -> Registrar datos de calidad S3 | E29: =IF(ISBLANK(Plan!B28),"",IF(Plan!O28>0,Plan!O28,""))
... C49: =IF(ISBLANK(Plan!B46),"",Plan!B46) -> Planificación | D49: =IF(ISBLANK(Plan!C46),"",Plan!C46) -> Realizar Diagrama de Gantt del Sprint 1 | E49: =IF(ISBLANK(Plan!B48),"",IF(Plan!O48>0,Plan!O48,"")) -> 5
C50: =IF(ISBLANK(Plan!#REF!),"",Plan!#REF!) -> #REF! | D50: =IF(ISBLANK(Plan!#REF!),"",Plan!#REF!) -> #REF! | E50: =IF(ISBLANK(Plan!B49),"",IF(Plan!O49>0,Plan!O49,""))
C51: =IF(ISBLANK(Plan!B47),"",Plan!B47) -> Planificación | D51: =IF(ISBLANK(Plan!C47),"",Plan!C47) -> Inspeccionar planes (Q) y poner en línea base (GCS) | E51: =IF(ISBLANK(Plan!B50),"",IF(Plan!O50>0,Plan!O50,""))
C52: =IF(ISBLANK(Plan!B48),"",Plan!B48) -> Planificación | D52: =IF(ISBLANK(Plan!C48),"",Plan!C48) -> Introducir datos de Planificación/Monitorización S5 (esfuerzo real / semana) | E52: =IF(ISBLANK(Plan!B51),"",IF(Plan!O51>0,Plan!O51,""))
C53: =IF(ISBLANK(Plan!B49),"",Plan!B49) -> Planificación | D53: =IF(ISBLANK(Plan!C49),"",Plan!C49) -> Registrar datos de calidad S5: revisiones, pruebas y defectos | E53: =IF(ISBLANK(Plan!B52),"",IF(Plan!O52>0,Plan!O52,"")) -> 5
C54: =IF(ISBLANK(Plan!B50),"",Plan!B50) | D54: =IF(ISBLANK(Plan!C50),"",Plan!C50) | E54: =IF(ISBLANK(Plan!B53),"",IF(Plan!O53>0,Plan!O53,""))
C55: =IF(ISBLANK(Plan!B51),"",Plan!B51) | D55: =IF(ISBLANK(Plan!C51),"",Plan!C51) | E55: =IF(ISBLANK(Plan!B54),"",IF(Plan!O54>0,Plan!O54,""))
C56: =IF(ISBLANK(Plan!B52),"",Plan!B52) -> Diseño | D56: =IF(ISBLANK(Plan!C52),"",Plan!C52) -> Realizar diagramas de Casos de Uso | E56: =IF(ISBLANK(Plan!B55),"",IF(Plan!O55>0,Plan!O55,"")) -> 5
C57: =IF(ISBLANK(Plan!B53),"",Plan!B53) -> Diseño | D57: =IF(ISBLANK(Plan!C53),"",Plan!C53) -> Realizar modelo Entidad/Relación y BBDD | E57: =IF(ISBLANK(Plan!B56),"",IF(Plan!O56>0,Plan!O56,"")) -> 60
C58: =IF(ISBLANK(Plan!B54),"",Plan!B54) -> Diseño | D58: =IF(ISBLANK(Plan!C54),"",Plan!C54) -> Diseñar pantallas | E58: =IF(ISBLANK(Plan!B57),"",IF(Plan!O57>0,Plan!O57,""))
C59: =IF(ISBLANK(Plan!B55),"",Plan!B55) -> Diseño | D59: =IF(ISBLANK(Plan!C55),"",Plan!C55) -> Inspeccionar diseño (Q) y poner en línea base (GCS) | E59: =IF(ISBLANK(Plan!B58),"",IF(Plan!O58>0,Plan!O58,""))
C60: =IF(ISBLANK(Plan!B56),"",Plan!B56) -> Diseño | D60: =IF(ISBLANK(Plan!C56),"",Plan!C56) -> Introducir datos de Planificación/Monitorización S6 (esfuerzo real / semana, US) | E60: =IF(ISBLANK(Plan!B59),"",IF(Plan!O59>0,Plan!O59,""))
C61: =IF(ISBLANK(Plan!B57),"",Plan!B57) | D61: =IF(ISBLANK(Plan!C57),"",Plan!C57) | E61: =IF(ISBLANK(Plan!B60),"",IF(Plan!O60>0,Plan!O60,""))
...

Sheet Desarrollo
C2: Lista de tareas de Desarrollo | G2: IMPORTANTE
D3: Total min. reales | E3: =SUM(E6:E88) -> #REF! | G3: ¡ NO EDITAR ESTA PÁGINA ! Se genera automaticamente
C5: Fase | D5: Actividad | E5: Esfuerzo (minutos reales)
C6: =IF(ISBLANK(Plan!B5),"",Plan!B5) -> Lanzamiento | D6: =IF(ISBLANK(Plan!C5),"",Plan!C5) -> Asignar equipos y roles | E6: =IF(ISBLANK(Plan!B5),"",IF(Plan!P5>0,Plan!P5,"")) -> 10
C7: =IF(ISBLANK(Plan!B6),"",Plan!B6) -> Lanzamiento | D7: =IF(ISBLANK(Plan!C6),"",Plan!C6) -> Definir proceso de reuniones | E7: =IF(ISBLANK(Plan!B6),"",IF(Plan!P6>0,Plan!P6,"")) -> 20
C8: =IF(ISBLANK(Plan!B7),"",Plan!B7) -> Lanzamiento | D8: =IF(ISBLANK(Plan!C7),"",Plan!C7) -> Realizar Estándar de Documentación | E8: =IF(ISBLANK(Plan!B7),"",IF(Plan!P7>0,Plan!P7,""))
C9: =IF(ISBLANK(Plan!B8),"",Plan!B8) -> Lanzamiento | D9: =IF(ISBLANK(Plan!C8),"",Plan!C8) -> Realizar Estándar de Agendas | E9: =IF(ISBLANK(Plan!B8),"",IF(Plan!P8>0,Plan!P8,"")) -> 15
C10: =IF(ISBLANK(Plan!B9),"",Plan!B9) -> Lanzamiento | D10: =IF(ISBLANK(Plan!C9),"",Plan!C9) -> Realizar Estándar de Actas | E10: =IF(ISBLANK(Plan!B9),"",IF(Plan!P9>0,Plan!P9,""))
C11: =IF(ISBLANK(Plan!B10),"",Plan!B10) -> Lanzamiento | D11: =IF(ISBLANK(Plan!C10),"",Plan!C10) -> Definir Ciclo de Vida a aplicar (actividades) | E11: =IF(ISBLANK(Plan!B10),"",IF(Plan!P10>0,Plan!P10,"")) -> 15
C12: =IF(ISBLANK(Plan!B11),"",Plan!B11) -> Lanzamiento | D12: =IF(ISBLANK(Plan!C11),"",Plan!C11) -> Definir outputs y plantillas del CV | E12: =IF(ISBLANK(Plan!B11),"",IF(Plan!P11>0,Plan!P11,""))
C13: =IF(ISBLANK(Plan!B12),"",Plan!B12) -> Lanzamiento | D13: =IF(ISBLANK(Plan!C12),"",Plan!C12) -> Definir Entorno de Desarrollo | E13: =IF(ISBLANK(Plan!B12),"",IF(Plan!P12>0,Plan!P12,"")) -> 20
C14: =IF(ISBLANK(Plan!B13),"",Plan!B13) -> Lanzamiento | D14: =IF(ISBLANK(Plan!C13),"",Plan!C13) -> Configurar Entorno de Desarrollo | E14: =IF(ISBLANK(Plan!B13),"",IF(Plan!P13>0,Plan!P13,""))
C15: =IF(ISBLANK(Plan!B14),"",Plan!B14) -> Lanzamiento | D15: =IF(ISBLANK(Plan!C14),"",Plan!C14) -> Definir Estándar de Codificación | E15: =IF(ISBLANK(Plan!B14),"",IF(Plan!P14>0,Plan!P14,"")) -> 15
C18: =IF(ISBLANK(Plan!B15),"",Plan!B15) -> Lanzamiento | D18: =IF(ISBLANK(Plan!C15),"",Plan!C15) -> Introducir datos de Planificación/Monitorización S1 (esfuerzo real / semana) | E18: =IF(ISBLANK(Plan!B15),"",IF(Plan!P15>0,Plan!P15,"")) -> 5
C19: =IF(ISBLANK(Plan!B16),"",Plan!B16) | D19: =IF(ISBLANK(Plan!C16),"",Plan!C16) | E19: =IF(ISBLANK(Plan!B16),"",IF(Plan!P16>0,Plan!P16,""))
C20: =IF(ISBLANK(Plan!B17),"",Plan!B17) | D20: =IF(ISBLANK(Plan!C17),"",Plan!C17) | E20: =IF(ISBLANK(Plan!B17),"",IF(Plan!P17>0,Plan!P17,""))
C21: =IF(ISBLANK(Plan!B18),"",Plan!B18) | D21: =IF(ISBLANK(Plan!C18),"",Plan!C18) | E21: =IF(ISBLANK(Plan!B18),"",IF(Plan!P18>0,Plan!P18,""))
C22: =IF(ISBLANK(Plan!B19),"",Plan!B19) -> Requisitos | D22: =IF(ISBLANK(Plan!C19),"",Plan!C19) -> Obtener Historias de Usuario (US) | E22: =IF(ISBLANK(Plan!B19),"",IF(Plan!P19>0,Plan!P19,"")) -> 30
C23: =IF(ISBLANK(Plan!B20),"",Plan!B20) -> Requisitos | D23: =IF(ISBLANK(Plan!C20),"",Plan!C20) -> Describir las US según plantilla (Como/Quiero/Para + criterios de aceptación) | E23: =IF(ISBLANK(Plan!B20),"",IF(Plan!P20>0,Plan!P20,"")) -> 5
C24: =IF(ISBLANK(Plan!B21),"",Plan!B21) -> Requisitos | D24: =IF(ISBLANK(Plan!C21),"",Plan!C21) -> Completar campos de US para puntos de función | E24: =IF(ISBLANK(Plan!B21),"",IF(Plan!P21>0,Plan!P21,"")) -> 180
C25: =IF(ISBLANK(Plan!B22),"",Plan!B22) -> Requisitos | D25: =IF(ISBLANK(Plan!C22),"",Plan!C22) -> Elaborar Product Backlog priorizado | E25: =IF(ISBLANK(Plan!B22),"",IF(Plan!P22>0,Plan!P22,"")) -> 10
C26: =IF(ISBLANK(Plan!B23),"",Plan!B23) -> Requisitos | D26: =IF(ISBLANK(Plan!C23),"",Plan!C23) -> Inspeccionar las US y criterios de aceptacion (Q) | E26: =IF(ISBLANK(Plan!B23),"",IF(Plan!P23>0,Plan!P23,"")) -> 60
C27: =IF(ISBLANK(Plan!B24),"",Plan!B24) -> Requisitos | D27: =IF(ISBLANK(Plan!C24),"",Plan!C24) -> Poner en línea base las US (GCS) | E27: =IF(ISBLANK(Plan!B24),"",IF(Plan!P24>0,Plan!P24,"")) -> 5
C28: =IF(ISBLANK(Plan!B25),"",Plan!B25) -> Requisitos | D28: =IF(ISBLANK(Plan!C25),"",Plan!C25) -> Introducir datos de Planificación/Monitorización(esfuerzo real / semana) S3 | E28: =IF(ISBLANK(Plan!B25),"",IF(Plan!P25>0,Plan!P25,"")) -> 120
C29: =IF(ISBLANK(Plan!B26),"",Plan!B26) -> Requisitos | D29: =IF(ISBLANK(Plan!C26),"",Plan!C26) -> Registrar datos de calidad S3 | E29: =IF(ISBLANK(Plan!B26),"",IF(Plan!P26>0,Plan!P26,"")) -> 10
... C49: =IF(ISBLANK(Plan!B46),"",Plan!B46) -> Planificación | D49: =IF(ISBLANK(Plan!C46),"",Plan!C46) -> Realizar Diagrama de Gantt del Sprint 1 | E49: =IF(ISBLANK(Plan!B46),"",IF(Plan!P46>0,Plan!P46,"")) -> 10
C50: =IF(ISBLANK(Plan!#REF!),"",Plan!#REF!) -> #REF! | D50: =IF(ISBLANK(Plan!#REF!),"",Plan!#REF!) -> #REF! | E50: =IF(ISBLANK(Plan!#REF!),"",IF(Plan!#REF!>0,Plan!#REF!,"")) -> #REF!
C51: =IF(ISBLANK(Plan!B47),"",Plan!B47) -> Planificación | D51: =IF(ISBLANK(Plan!C47),"",Plan!C47) -> Inspeccionar planes (Q) y poner en línea base (GCS) | E51: =IF(ISBLANK(Plan!B47),"",IF(Plan!P47>0,Plan!P47,""))
C52: =IF(ISBLANK(Plan!B48),"",Plan!B48) -> Planificación | D52: =IF(ISBLANK(Plan!C48),"",Plan!C48) -> Introducir datos de Planificación/Monitorización S5 (esfuerzo real / semana) | E52: =IF(ISBLANK(Plan!B48),"",IF(Plan!P48>0,Plan!P48,"")) -> 5
C53: =IF(ISBLANK(Plan!B49),"",Plan!B49) -> Planificación | D53: =IF(ISBLANK(Plan!C49),"",Plan!C49) -> Registrar datos de calidad S5: revisiones, pruebas y defectos | E53: =IF(ISBLANK(Plan!B49),"",IF(Plan!P49>0,Plan!P49,"")) -> 40
C54: =IF(ISBLANK(Plan!B50),"",Plan!B50) | D54: =IF(ISBLANK(Plan!C50),"",Plan!C50) | E54: =IF(ISBLANK(Plan!B50),"",IF(Plan!P50>0,Plan!P50,""))
C55: =IF(ISBLANK(Plan!B51),"",Plan!B51) | D55: =IF(ISBLANK(Plan!C51),"",Plan!C51) | E55: =IF(ISBLANK(Plan!B51),"",IF(Plan!P51>0,Plan!P51,""))
C56: =IF(ISBLANK(Plan!B52),"",Plan!B52) -> Diseño | D56: =IF(ISBLANK(Plan!C52),"",Plan!C52) -> Realizar diagramas de Casos de Uso | E56: =IF(ISBLANK(Plan!B52),"",IF(Plan!P52>0,Plan!P52,"")) -> 25
C57: =IF(ISBLANK(Plan!B53),"",Plan!B53) -> Diseño | D57: =IF(ISBLANK(Plan!C53),"",Plan!C53) -> Realizar modelo Entidad/Relación y BBDD | E57: =IF(ISBLANK(Plan!B53),"",IF(Plan!P53>0,Plan!P53,""))
C58: =IF(ISBLANK(Plan!B54),"",Plan!B54) -> Diseño | D58: =IF(ISBLANK(Plan!C54),"",Plan!C54) -> Diseñar pantallas | E58: =IF(ISBLANK(Plan!B54),"",IF(Plan!P54>0,Plan!P54,""))
C59: =IF(ISBLANK(Plan!B55),"",Plan!B55) -> Diseño | D59: =IF(ISBLANK(Plan!C55),"",Plan!C55) -> Inspeccionar diseño (Q) y poner en línea base (GCS) | E59: =IF(ISBLANK(Plan!B55),"",IF(Plan!P55>0,Plan!P55,"")) -> 5
C60: =IF(ISBLANK(Plan!B56),"",Plan!B56) -> Diseño | D60: =IF(ISBLANK(Plan!C56),"",Plan!C56) -> Introducir datos de Planificación/Monitorización S6 (esfuerzo real / semana, US) | E60: =IF(ISBLANK(Plan!B56),"",IF(Plan!P56>0,Plan!P56,"")) -> 10
C61: =IF(ISBLANK(Plan!B57),"",Plan!B57) | D61: =IF(ISBLANK(Plan!C57),"",Plan!C57) | E61: =IF(ISBLANK(Plan!B57),"",IF(Plan!P57>0,Plan!P57,""))
C62: =IF(ISBLANK(Plan!B58),"",Plan!B58) | D62: =IF(ISBLANK(Plan!C58),"",Plan!C58) | E62: =IF(ISBLANK(Plan!B58),"",IF(Plan!P58>0,Plan!P58,""))
... C73: =IF(ISBLANK(Plan!B69),"",Plan!B69) -> Implementación | D73: =IF(ISBLANK(Plan!C69),"",Plan!C69) -> Registrar datos de calidad S7: ejecucion, defectos y verificacion DoD | E73: =IF(ISBLANK(Plan!B69),"",IF(Plan!P69>0,Plan!P69,""))
...

Sheet Cambios
C2: Lista de tareas de Cambios | G2: IMPORTANTE
D3: Total min. reales | E3: =SUM(E6:E88) -> #REF! | G3: ¡ NO EDITAR ESTA PÁGINA ! Se genera automaticamente
C5: Fase | D5: Actividad | E5: Esfuerzo (minutos reales)
C6: =IF(ISBLANK(Plan!B5),"",Plan!B5) -> Lanzamiento | D6: =IF(ISBLANK(Plan!C5),"",Plan!C5) -> Asignar equipos y roles | E6: =IF(ISBLANK(Plan!B5),"",IF(Plan!Q5>0,Plan!Q5,"")) -> 10
C7: =IF(ISBLANK(Plan!B6),"",Plan!B6) -> Lanzamiento | D7: =IF(ISBLANK(Plan!C6),"",Plan!C6) -> Definir proceso de reuniones | E7: =IF(ISBLANK(Plan!B6),"",IF(Plan!Q6>0,Plan!Q6,"")) -> 20
C8: =IF(ISBLANK(Plan!B7),"",Plan!B7) -> Lanzamiento | D8: =IF(ISBLANK(Plan!C7),"",Plan!C7) -> Realizar Estándar de Documentación | E8: =IF(ISBLANK(Plan!B7),"",IF(Plan!Q7>0,Plan!Q7,""))
C9: =IF(ISBLANK(Plan!B8),"",Plan!B8) -> Lanzamiento | D9: =IF(ISBLANK(Plan!C8),"",Plan!C8) -> Realizar Estándar de Agendas | E9: =IF(ISBLANK(Plan!B8),"",IF(Plan!Q8>0,Plan!Q8,"")) -> 15
C10: =IF(ISBLANK(Plan!B9),"",Plan!B9) -> Lanzamiento | D10: =IF(ISBLANK(Plan!C9),"",Plan!C9) -> Realizar Estándar de Actas | E10: =IF(ISBLANK(Plan!B9),"",IF(Plan!Q9>0,Plan!Q9,""))
C11: =IF(ISBLANK(Plan!B10),"",Plan!B10) -> Lanzamiento | D11: =IF(ISBLANK(Plan!C10),"",Plan!C10) -> Definir Ciclo de Vida a aplicar (actividades) | E11: =IF(ISBLANK(Plan!B10),"",IF(Plan!Q10>0,Plan!Q10,"")) -> 15
C12: =IF(ISBLANK(Plan!B11),"",Plan!B11) -> Lanzamiento | D12: =IF(ISBLANK(Plan!C11),"",Plan!C11) -> Definir outputs y plantillas del CV | E12: =IF(ISBLANK(Plan!B11),"",IF(Plan!Q11>0,Plan!Q11,""))
C13: =IF(ISBLANK(Plan!B12),"",Plan!B12) -> Lanzamiento | D13: =IF(ISBLANK(Plan!C12),"",Plan!C12) -> Definir Entorno de Desarrollo | E13: =IF(ISBLANK(Plan!B12),"",IF(Plan!Q12>0,Plan!Q12,"")) -> 10
C14: =IF(ISBLANK(Plan!B13),"",Plan!B13) -> Lanzamiento | D14: =IF(ISBLANK(Plan!C13),"",Plan!C13) -> Configurar Entorno de Desarrollo | E14: =IF(ISBLANK(Plan!B13),"",IF(Plan!Q13>0,Plan!Q13,""))
C15: =IF(ISBLANK(Plan!B14),"",Plan!B14) -> Lanzamiento | D15: =IF(ISBLANK(Plan!C14),"",Plan!C14) -> Definir Estándar de Codificación | E15: =IF(ISBLANK(Plan!B14),"",IF(Plan!Q14>0,Plan!Q14,"")) -> 10
C18: =IF(ISBLANK(Plan!B15),"",Plan!B15) -> Lanzamiento | D18: =IF(ISBLANK(Plan!C15),"",Plan!C15) -> Introducir datos de Planificación/Monitorización S1 (esfuerzo real / semana) | E18: =IF(ISBLANK(Plan!B15),"",IF(Plan!Q15>0,Plan!Q15,"")) -> 5
C19: =IF(ISBLANK(Plan!B16),"",Plan!B16) | D19: =IF(ISBLANK(Plan!C16),"",Plan!C16) | E19: =IF(ISBLANK(Plan!B16),"",IF(Plan!Q16>0,Plan!Q16,""))
C20: =IF(ISBLANK(Plan!B17),"",Plan!B17) | D20: =IF(ISBLANK(Plan!C17),"",Plan!C17) | E20: =IF(ISBLANK(Plan!B17),"",IF(Plan!Q17>0,Plan!Q17,""))
C21: =IF(ISBLANK(Plan!B18),"",Plan!B18) | D21: =IF(ISBLANK(Plan!C18),"",Plan!C18) | E21: =IF(ISBLANK(Plan!B18),"",IF(Plan!Q18>0,Plan!Q18,""))
C22: =IF(ISBLANK(Plan!B19),"",Plan!B19) -> Requisitos | D22: =IF(ISBLANK(Plan!C19),"",Plan!C19) -> Obtener Historias de Usuario (US) | E22: =IF(ISBLANK(Plan!B19),"",IF(Plan!Q19>0,Plan!Q19,""))
C23: =IF(ISBLANK(Plan!B20),"",Plan!B20) -> Requisitos | D23: =IF(ISBLANK(Plan!C20),"",Plan!C20) -> Describir las US según plantilla (Como/Quiero/Para + criterios de aceptación) | E23: =IF(ISBLANK(Plan!B20),"",IF(Plan!Q20>0,Plan!Q20,""))
C24: =IF(ISBLANK(Plan!B21),"",Plan!B21) -> Requisitos | D24: =IF(ISBLANK(Plan!C21),"",Plan!C21) -> Completar campos de US para puntos de función | E24: =IF(ISBLANK(Plan!B21),"",IF(Plan!Q21>0,Plan!Q21,""))
C25: =IF(ISBLANK(Plan!B22),"",Plan!B22) -> Requisitos | D25: =IF(ISBLANK(Plan!C22),"",Plan!C22) -> Elaborar Product Backlog priorizado | E25: =IF(ISBLANK(Plan!B22),"",IF(Plan!Q22>0,Plan!Q22,""))
C26: =IF(ISBLANK(Plan!B23),"",Plan!B23) -> Requisitos | D26: =IF(ISBLANK(Plan!C23),"",Plan!C23) -> Inspeccionar las US y criterios de aceptacion (Q) | E26: =IF(ISBLANK(Plan!B23),"",IF(Plan!Q23>0,Plan!Q23,""))
C27: =IF(ISBLANK(Plan!B24),"",Plan!B24) -> Requisitos | D27: =IF(ISBLANK(Plan!C24),"",Plan!C24) -> Poner en línea base las US (GCS) | E27: =IF(ISBLANK(Plan!B24),"",IF(Plan!Q24>0,Plan!Q24,""))
C28: =IF(ISBLANK(Plan!B25),"",Plan!B25) -> Requisitos | D28: =IF(ISBLANK(Plan!C25),"",Plan!C25) -> Introducir datos de Planificación/Monitorización(esfuerzo real / semana) S3 | E28: =IF(ISBLANK(Plan!B25),"",IF(Plan!Q25>0,Plan!Q25,""))
C29: =IF(ISBLANK(Plan!B26),"",Plan!B26) -> Requisitos | D29: =IF(ISBLANK(Plan!C26),"",Plan!C26) -> Registrar datos de calidad S3 | E29: =IF(ISBLANK(Plan!B26),"",IF(Plan!Q26>0,Plan!Q26,""))
... C49: =IF(ISBLANK(Plan!B46),"",Plan!B46) -> Planificación | D49: =IF(ISBLANK(Plan!C46),"",Plan!C46) -> Realizar Diagrama de Gantt del Sprint 1 | E49: =IF(ISBLANK(Plan!B46),"",IF(Plan!Q46>0,Plan!Q46,""))
C50: =IF(ISBLANK(Plan!#REF!),"",Plan!#REF!) -> #REF! | D50: =IF(ISBLANK(Plan!#REF!),"",Plan!#REF!) -> #REF! | E50: =IF(ISBLANK(Plan!#REF!),"",IF(Plan!#REF!>0,Plan!#REF!,"")) -> #REF!
C51: =IF(ISBLANK(Plan!B47),"",Plan!B47) -> Planificación | D51: =IF(ISBLANK(Plan!C47),"",Plan!C47) -> Inspeccionar planes (Q) y poner en línea base (GCS) | E51: =IF(ISBLANK(Plan!B47),"",IF(Plan!Q47>0,Plan!Q47,""))
C52: =IF(ISBLANK(Plan!B48),"",Plan!B48) -> Planificación | D52: =IF(ISBLANK(Plan!C48),"",Plan!C48) -> Introducir datos de Planificación/Monitorización S5 (esfuerzo real / semana) | E52: =IF(ISBLANK(Plan!B48),"",IF(Plan!Q48>0,Plan!Q48,""))
C53: =IF(ISBLANK(Plan!B49),"",Plan!B49) -> Planificación | D53: =IF(ISBLANK(Plan!C49),"",Plan!C49) -> Registrar datos de calidad S5: revisiones, pruebas y defectos | E53: =IF(ISBLANK(Plan!B49),"",IF(Plan!Q49>0,Plan!Q49,""))
C54: =IF(ISBLANK(Plan!B50),"",Plan!B50) | D54: =IF(ISBLANK(Plan!C50),"",Plan!C50) | E54: =IF(ISBLANK(Plan!B50),"",IF(Plan!Q50>0,Plan!Q50,""))
C55: =IF(ISBLANK(Plan!B51),"",Plan!B51) | D55: =IF(ISBLANK(Plan!C51),"",Plan!C51) | E55: =IF(ISBLANK(Plan!B51),"",IF(Plan!Q51>0,Plan!Q51,""))
C56: =IF(ISBLANK(Plan!B52),"",Plan!B52) -> Diseño | D56: =IF(ISBLANK(Plan!C52),"",Plan!C52) -> Realizar diagramas de Casos de Uso | E56: =IF(ISBLANK(Plan!B52),"",IF(Plan!Q52>0,Plan!Q52,""))
C57: =IF(ISBLANK(Plan!B53),"",Plan!B53) -> Diseño | D57: =IF(ISBLANK(Plan!C53),"",Plan!C53) -> Realizar modelo Entidad/Relación y BBDD | E57: =IF(ISBLANK(Plan!B53),"",IF(Plan!Q53>0,Plan!Q53,""))
C58: =IF(ISBLANK(Plan!B54),"",Plan!B54) -> Diseño | D58: =IF(ISBLANK(Plan!C54),"",Plan!C54) -> Diseñar pantallas | E58: =IF(ISBLANK(Plan!B54),"",IF(Plan!Q54>0,Plan!Q54,""))
C59: =IF(ISBLANK(Plan!B55),"",Plan!B55) -> Diseño | D59: =IF(ISBLANK(Plan!C55),"",Plan!C55) -> Inspeccionar diseño (Q) y poner en línea base (GCS) | E59: =IF(ISBLANK(Plan!B55),"",IF(Plan!Q55>0,Plan!Q55,""))
C60: =IF(ISBLANK(Plan!B56),"",Plan!B56) -> Diseño | D60: =IF(ISBLANK(Plan!C56),"",Plan!C56) -> Introducir datos de Planificación/Monitorización S6 (esfuerzo real / semana, US) | E60: =IF(ISBLANK(Plan!B56),"",IF(Plan!Q56>0,Plan!Q56,""))
C61: =IF(ISBLANK(Plan!B57),"",Plan!B57) | D61: =IF(ISBLANK(Plan!C57),"",Plan!C57) | E61: =IF(ISBLANK(Plan!B57),"",IF(Plan!Q57>0,Plan!Q57,""))
C62: =IF(ISBLANK(Plan!B58),"",Plan!B58) | D62: =IF(ISBLANK(Plan!C58),"",Plan!C58) | E62: =IF(ISBLANK(Plan!B58),"",IF(Plan!Q58>0,Plan!Q58,""))
... C73: =IF(ISBLANK(Plan!B69),"",Plan!B69) -> Implementación | D73: =IF(ISBLANK(Plan!C69),"",Plan!C69) -> Registrar datos de calidad S7: ejecucion, defectos y verificacion DoD | E73: =IF(ISBLANK(Plan!B69),"",IF(Plan!Q69>0,Plan!Q69,""))
...

Sheet Calidad
C2: Lista de tareas de Calidad | G2: IMPORTANTE
D3: Total min. reales | E3: =SUM(E6:E88) -> #REF! | G3: ¡ NO EDITAR ESTA PÁGINA ! Se genera automaticamente
C5: Fase | D5: Actividad | E5: Esfuerzo (minutos reales)
C6: =IF(ISBLANK(Plan!B5),"",Plan!B5) -> Lanzamiento | D6: =IF(ISBLANK(Plan!C5),"",Plan!C5) -> Asignar equipos y roles | E6: =IF(ISBLANK(Plan!B5),"",IF(Plan!R5>0,Plan!R5,"")) -> 10
C7: =IF(ISBLANK(Plan!B6),"",Plan!B6) -> Lanzamiento | D7: =IF(ISBLANK(Plan!C6),"",Plan!C6) -> Definir proceso de reuniones | E7: =IF(ISBLANK(Plan!B6),"",IF(Plan!R6>0,Plan!R6,"")) -> 20
C8: =IF(ISBLANK(Plan!B7),"",Plan!B7) -> Lanzamiento | D8: =IF(ISBLANK(Plan!C7),"",Plan!C7) -> Realizar Estándar de Documentación | E8: =IF(ISBLANK(Plan!B7),"",IF(Plan!R7>0,Plan!R7,"")) -> 20
C9: =IF(ISBLANK(Plan!B8),"",Plan!B8) -> Lanzamiento | D9: =IF(ISBLANK(Plan!C8),"",Plan!C8) -> Realizar Estándar de Agendas | E9: =IF(ISBLANK(Plan!B8),"",IF(Plan!R8>0,Plan!R8,"")) -> 10
C10: =IF(ISBLANK(Plan!B9),"",Plan!B9) -> Lanzamiento | D10: =IF(ISBLANK(Plan!C9),"",Plan!C9) -> Realizar Estándar de Actas | E10: =IF(ISBLANK(Plan!B9),"",IF(Plan!R9>0,Plan!R9,""))
C11: =IF(ISBLANK(Plan!B10),"",Plan!B10) -> Lanzamiento | D11: =IF(ISBLANK(Plan!C10),"",Plan!C10) -> Definir Ciclo de Vida a aplicar (actividades) | E11: =IF(ISBLANK(Plan!B10),"",IF(Plan!R10>0,Plan!R10,"")) -> 10
C12: =IF(ISBLANK(Plan!B11),"",Plan!B11) -> Lanzamiento | D12: =IF(ISBLANK(Plan!C11),"",Plan!C11) -> Definir outputs y plantillas del CV | E12: =IF(ISBLANK(Plan!B11),"",IF(Plan!R11>0,Plan!R11,""))
C13: =IF(ISBLANK(Plan!B12),"",Plan!B12) -> Lanzamiento | D13: =IF(ISBLANK(Plan!C12),"",Plan!C12) -> Definir Entorno de Desarrollo | E13: =IF(ISBLANK(Plan!B12),"",IF(Plan!R12>0,Plan!R12,"")) -> 15
C14: =IF(ISBLANK(Plan!B13),"",Plan!B13) -> Lanzamiento | D14: =IF(ISBLANK(Plan!C13),"",Plan!C13) -> Configurar Entorno de Desarrollo | E14: =IF(ISBLANK(Plan!B13),"",IF(Plan!R13>0,Plan!R13,""))
C15: =IF(ISBLANK(Plan!B14),"",Plan!B14) -> Lanzamiento | D15: =IF(ISBLANK(Plan!C14),"",Plan!C14) -> Definir Estándar de Codificación | E15: =IF(ISBLANK(Plan!B14),"",IF(Plan!R14>0,Plan!R14,"")) -> 10
C18: =IF(ISBLANK(Plan!B15),"",Plan!B15) -> Lanzamiento | D18: =IF(ISBLANK(Plan!C15),"",Plan!C15) -> Introducir datos de Planificación/Monitorización S1 (esfuerzo real / semana) | E18: =IF(ISBLANK(Plan!B15),"",IF(Plan!R15>0,Plan!R15,"")) -> 5
C19: =IF(ISBLANK(Plan!B16),"",Plan!B16) | D19: =IF(ISBLANK(Plan!C16),"",Plan!C16) | E19: =IF(ISBLANK(Plan!B16),"",IF(Plan!R16>0,Plan!R16,""))
C20: =IF(ISBLANK(Plan!B17),"",Plan!B17) | D20: =IF(ISBLANK(Plan!C17),"",Plan!C17) | E20: =IF(ISBLANK(Plan!B17),"",IF(Plan!R17>0,Plan!R17,""))
C21: =IF(ISBLANK(Plan!B18),"",Plan!B18) | D21: =IF(ISBLANK(Plan!C18),"",Plan!C18) | E21: =IF(ISBLANK(Plan!B18),"",IF(Plan!R18>0,Plan!R18,""))
C22: =IF(ISBLANK(Plan!B19),"",Plan!B19) -> Requisitos | D22: =IF(ISBLANK(Plan!C19),"",Plan!C19) -> Obtener Historias de Usuario (US) | E22: =IF(ISBLANK(Plan!B19),"",IF(Plan!R19>0,Plan!R19,""))
C23: =IF(ISBLANK(Plan!B20),"",Plan!B20) -> Requisitos | D23: =IF(ISBLANK(Plan!C20),"",Plan!C20) -> Describir las US según plantilla (Como/Quiero/Para + criterios de aceptación) | E23: =IF(ISBLANK(Plan!B20),"",IF(Plan!R20>0,Plan!R20,""))
C24: =IF(ISBLANK(Plan!B21),"",Plan!B21) -> Requisitos | D24: =IF(ISBLANK(Plan!C21),"",Plan!C21) -> Completar campos de US para puntos de función | E24: =IF(ISBLANK(Plan!B21),"",IF(Plan!R21>0,Plan!R21,""))
C25: =IF(ISBLANK(Plan!B22),"",Plan!B22) -> Requisitos | D25: =IF(ISBLANK(Plan!C22),"",Plan!C22) -> Elaborar Product Backlog priorizado | E25: =IF(ISBLANK(Plan!B22),"",IF(Plan!R22>0,Plan!R22,""))
C26: =IF(ISBLANK(Plan!B23),"",Plan!B23) -> Requisitos | D26: =IF(ISBLANK(Plan!C23),"",Plan!C23) -> Inspeccionar las US y criterios de aceptacion (Q) | E26: =IF(ISBLANK(Plan!B23),"",IF(Plan!R23>0,Plan!R23,""))
C27: =IF(ISBLANK(Plan!B24),"",Plan!B24) -> Requisitos | D27: =IF(ISBLANK(Plan!C24),"",Plan!C24) -> Poner en línea base las US (GCS) | E27: =IF(ISBLANK(Plan!B24),"",IF(Plan!R24>0,Plan!R24,""))
C28: =IF(ISBLANK(Plan!B25),"",Plan!B25) -> Requisitos | D28: =IF(ISBLANK(Plan!C25),"",Plan!C25) -> Introducir datos de Planificación/Monitorización(esfuerzo real / semana) S3 | E28: =IF(ISBLANK(Plan!B25),"",IF(Plan!R25>0,Plan!R25,""))
C29: =IF(ISBLANK(Plan!B26),"",Plan!B26) -> Requisitos | D29: =IF(ISBLANK(Plan!C26),"",Plan!C26) -> Registrar datos de calidad S3 | E29: =IF(ISBLANK(Plan!B26),"",IF(Plan!R26>0,Plan!R26,""))
... C49: =IF(ISBLANK(Plan!B46),"",Plan!B46) -> Planificación | D49: =IF(ISBLANK(Plan!C46),"",Plan!C46) -> Realizar Diagrama de Gantt del Sprint 1 | E49: =IF(ISBLANK(Plan!B46),"",IF(Plan!R46>0,Plan!R46,""))
C50: =IF(ISBLANK(Plan!#REF!),"",Plan!#REF!) -> #REF! | D50: =IF(ISBLANK(Plan!#REF!),"",Plan!#REF!) -> #REF! | E50: =IF(ISBLANK(Plan!#REF!),"",IF(Plan!#REF!>0,Plan!#REF!,"")) -> #REF!
C51: =IF(ISBLANK(Plan!B47),"",Plan!B47) -> Planificación | D51: =IF(ISBLANK(Plan!C47),"",Plan!C47) -> Inspeccionar planes (Q) y poner en línea base (GCS) | E51: =IF(ISBLANK(Plan!B47),"",IF(Plan!R47>0,Plan!R47,""))
C52: =IF(ISBLANK(Plan!B48),"",Plan!B48) -> Planificación | D52: =IF(ISBLANK(Plan!C48),"",Plan!C48) -> Introducir datos de Planificación/Monitorización S5 (esfuerzo real / semana) | E52: =IF(ISBLANK(Plan!B48),"",IF(Plan!R48>0,Plan!R48,""))
C53: =IF(ISBLANK(Plan!B49),"",Plan!B49) -> Planificación | D53: =IF(ISBLANK(Plan!C49),"",Plan!C49) -> Registrar datos de calidad S5: revisiones, pruebas y defectos | E53: =IF(ISBLANK(Plan!B49),"",IF(Plan!R49>0,Plan!R49,""))
C54: =IF(ISBLANK(Plan!B50),"",Plan!B50) | D54: =IF(ISBLANK(Plan!C50),"",Plan!C50) | E54: =IF(ISBLANK(Plan!B50),"",IF(Plan!R50>0,Plan!R50,""))
C55: =IF(ISBLANK(Plan!B51),"",Plan!B51) | D55: =IF(ISBLANK(Plan!C51),"",Plan!C51) | E55: =IF(ISBLANK(Plan!B51),"",IF(Plan!R51>0,Plan!R51,""))
C56: =IF(ISBLANK(Plan!B52),"",Plan!B52) -> Diseño | D56: =IF(ISBLANK(Plan!C52),"",Plan!C52) -> Realizar diagramas de Casos de Uso | E56: =IF(ISBLANK(Plan!B52),"",IF(Plan!R52>0,Plan!R52,""))
C57: =IF(ISBLANK(Plan!B53),"",Plan!B53) -> Diseño | D57: =IF(ISBLANK(Plan!C53),"",Plan!C53) -> Realizar modelo Entidad/Relación y BBDD | E57: =IF(ISBLANK(Plan!B53),"",IF(Plan!R53>0,Plan!R53,""))
C58: =IF(ISBLANK(Plan!B54),"",Plan!B54) -> Diseño | D58: =IF(ISBLANK(Plan!C54),"",Plan!C54) -> Diseñar pantallas | E58: =IF(ISBLANK(Plan!B54),"",IF(Plan!R54>0,Plan!R54,""))
C59: =IF(ISBLANK(Plan!B55),"",Plan!B55) -> Diseño | D59: =IF(ISBLANK(Plan!C55),"",Plan!C55) -> Inspeccionar diseño (Q) y poner en línea base (GCS) | E59: =IF(ISBLANK(Plan!B55),"",IF(Plan!R55>0,Plan!R55,""))
C60: =IF(ISBLANK(Plan!B56),"",Plan!B56) -> Diseño | D60: =IF(ISBLANK(Plan!C56),"",Plan!C56) -> Introducir datos de Planificación/Monitorización S6 (esfuerzo real / semana, US) | E60: =IF(ISBLANK(Plan!B56),"",IF(Plan!R56>0,Plan!R56,""))
C61: =IF(ISBLANK(Plan!B57),"",Plan!B57) | D61: =IF(ISBLANK(Plan!C57),"",Plan!C57) | E61: =IF(ISBLANK(Plan!B57),"",IF(Plan!R57>0,Plan!R57,""))
C62: =IF(ISBLANK(Plan!B58),"",Plan!B58) | D62: =IF(ISBLANK(Plan!C58),"",Plan!C58) | E62: =IF(ISBLANK(Plan!B58),"",IF(Plan!R58>0,Plan!R58,""))
... C73: =IF(ISBLANK(Plan!B69),"",Plan!B69) -> Implementación | D73: =IF(ISBLANK(Plan!C69),"",Plan!C69) -> Registrar datos de calidad S7: ejecucion, defectos y verificacion DoD | E73: =IF(ISBLANK(Plan!B69),"",IF(Plan!R69>0,Plan!R69,""))
...

Sheet Horas Estimadas
I6: Carga de horas estimadas por rol/semana
J8: Total | K8: 1 | L8: 2 | M8: 3 | N8: 4 | O8: 5 | P8: 6 | Q8: 7 | R8: 8 | S8: 9
I9: Líder / Scrum Master | J9: =SUM(K9:S9) -> 33 | K9: =SUMIFS(Plan!$D$5:$D$83,Plan!$L$5:$L$83,K$8)/60 -> 3.25 | L9: =SUMIFS(Plan!$D$5:$D$83,Plan!$L$5:$L$83,L$8)/60 -> 0.41666667 | M9: =SUMIFS(Plan!$D$5:$D$83,Plan!$L$5:$L$83,M$8)/60 -> 0.83333333 | N9: =SUMIFS(Plan!$D$5:$D$83,Plan!$L$5:$L$83,N$8)/60 -> 3.75 | O9: =SUMIFS(Plan!$D$5:$D$83,Plan!$L$5:$L$83,O$8)/60 -> 0.91666667 | P9: =SUMIFS(Plan!$D$5:$D$83,Plan!$L$5:$L$83,P$8)/60 -> 0.75 | Q9: =SUMIFS(Plan!$D$5:$D$83,Plan!$L$5:$L$83,Q$8)/60 -> 14.083333 | R9: =SUMIFS(Plan!$D$5:$D$83,Plan!$L$5:$L$83,R$8)/60 -> 4.5833333 | S9: =SUMIFS(Plan!$D$5:$D$83,Plan!$L$5:$L$83,S$8)/60 -> 4.4166667
I10: Product Owner | J10: =SUM(K10:S10) -> 32.833333 | K10: =SUMIFS(Plan!$E$5:$E$83,Plan!$L$5:$L$83,K$8)/60 -> 3 | L10: =SUMIFS(Plan!$E$5:$E$83,Plan!$L$5:$L$83,L$8)/60 -> 0.41666667 | M10: =SUMIFS(Plan!$E$5:$E$83,Plan!$L$5:$L$83,M$8)/60 -> 6 | N10: =SUMIFS(Plan!$E$5:$E$83,Plan!$L$5:$L$83,N$8)/60 -> 1.1666667 | O10: =SUMIFS(Plan!$E$5:$E$83,Plan!$L$5:$L$83,O$8)/60 -> 1.25 | P10: =SUMIFS(Plan!$E$5:$E$83,Plan!$L$5:$L$83,P$8)/60 -> 0.91666667 | Q10: =SUMIFS(Plan!$E$5:$E$83,Plan!$L$5:$L$83,Q$8)/60 -> 14.083333 | R10: =SUMIFS(Plan!$E$5:$E$83,Plan!$L$5:$L$83,R$8)/60 -> 4.5833333 | S10: =SUMIFS(Plan!$E$5:$E$83,Plan!$L$5:$L$83,S$8)/60 -> 1.4166667
I11: Planificación | J11: =SUM(K11:S11) -> 30.25 | K11: =SUMIFS(Plan!$F$5:$F$83,Plan!$L$5:$L$83,K$8)/60 -> 2.6666667 | L11: =SUMIFS(Plan!$F$5:$F$83,Plan!$L$5:$L$83,L$8)/60 -> 0.41666667 | M11: =SUMIFS(Plan!$F$5:$F$83,Plan!$L$5:$L$83,M$8)/60 -> 1 | N11: =SUMIFS(Plan!$F$5:$F$83,Plan!$L$5:$L$83,N$8)/60 -> 3.9166667 | O11: =SUMIFS(Plan!$F$5:$F$83,Plan!$L$5:$L$83,O$8)/60 -> 1.25 | P11: =SUMIFS(Plan!$F$5:$F$83,Plan!$L$5:$L$83,P$8)/60 -> 0.91666667 | Q11: =SUMIFS(Plan!$F$5:$F$83,Plan!$L$5:$L$83,Q$8)/60 -> 14.083333 | R11: =SUMIFS(Plan!$F$5:$F$83,Plan!$L$5:$L$83,R$8)/60 -> 4.5833333 | S11: =SUMIFS(Plan!$F$5:$F$83,Plan!$L$5:$L$83,S$8)/60 -> 1.4166667
I12: Desarrollo | J12: =SUM(K12:S12) -> 34.75 | K12: =SUMIFS(Plan!$G$5:$G$83,Plan!$L$5:$L$83,K$8)/60 -> 2.6666667 | L12: =SUMIFS(Plan!$G$5:$G$83,Plan!$L$5:$L$83,L$8)/60 -> 0.41666667 | M12: =SUMIFS(Plan!$G$5:$G$83,Plan!$L$5:$L$83,M$8)/60 -> 3 | N12: =SUMIFS(Plan!$G$5:$G$83,Plan!$L$5:$L$83,N$8)/60 -> 1.4166667 | O12: =SUMIFS(Plan!$G$5:$G$83,Plan!$L$5:$L$83,O$8)/60 -> 4.25 | P12: =SUMIFS(Plan!$G$5:$G$83,Plan!$L$5:$L$83,P$8)/60 -> 2.9166667 | Q12: =SUMIFS(Plan!$G$5:$G$83,Plan!$L$5:$L$83,Q$8)/60 -> 14.083333 | R12: =SUMIFS(Plan!$G$5:$G$83,Plan!$L$5:$L$83,R$8)/60 -> 4.5833333 | S12: =SUMIFS(Plan!$G$5:$G$83,Plan!$L$5:$L$83,S$8)/60 -> 1.4166667
I13: Cambios | J13: =SUM(K13:S13) -> 2.6666667 | K13: =SUMIFS(Plan!$H$5:$H$83,Plan!$L$5:$L$83,K$8)/60 -> 2.6666667 | L13: =SUMIFS(Plan!$H$5:$H$83,Plan!$L$5:$L$83,L$8)/60 -> 0 | M13: =SUMIFS(Plan!$H$5:$H$83,Plan!$L$5:$L$83,M$8)/60 -> 0 | N13: =SUMIFS(Plan!$H$5:$H$83,Plan!$L$5:$L$83,N$8)/60 -> 0 | O13: =SUMIFS(Plan!$H$5:$H$83,Plan!$L$5:$L$83,O$8)/60 -> 0 | P13: =SUMIFS(Plan!$H$5:$H$83,Plan!$L$5:$L$83,P$8)/60 -> 0 | Q13: =SUMIFS(Plan!$H$5:$H$83,Plan!$L$5:$L$83,Q$8)/60 -> 0 | R13: =SUMIFS(Plan!$H$5:$H$83,Plan!$L$5:$L$83,R$8)/60 -> 0 | S13: =SUMIFS(Plan!$H$5:$H$83,Plan!$L$5:$L$83,S$8)/60 -> 0
I14: Calidad | J14: =SUM(K14:S14) -> 2.6666667 | K14: =SUMIFS(Plan!$I$5:$I$83,Plan!$L$5:$L$83,K$8)/60 -> 2.6666667 | L14: =SUMIFS(Plan!$I$5:$I$83,Plan!$L$5:$L$83,L$8)/60 -> 0 | M14: =SUMIFS(Plan!$I$5:$I$83,Plan!$L$5:$L$83,M$8)/60 -> 0 | N14: =SUMIFS(Plan!$I$5:$I$83,Plan!$L$5:$L$83,N$8)/60 -> 0 | O14: =SUMIFS(Plan!$I$5:$I$83,Plan!$L$5:$L$83,O$8)/60 -> 0 | P14: =SUMIFS(Plan!$I$5:$I$83,Plan!$L$5:$L$83,P$8)/60 -> 0 | Q14: =SUMIFS(Plan!$I$5:$I$83,Plan!$L$5:$L$83,Q$8)/60 -> 0 | R14: =SUMIFS(Plan!$I$5:$I$83,Plan!$L$5:$L$83,R$8)/60 -> 0 | S14: =SUMIFS(Plan!$I$5:$I$83,Plan!$L$5:$L$83,S$8)/60 -> 0
I16: IMPORTANTE
I17: ¡ NO EDITAR ESTA PÁGINA ! Se genera automaticamente
I23: Carga de horas estimadas por fase
I25: Fase | J25: Horas
I26: Lanzamiento | J26: =SUMIFS(Plan!$J$5:$J$83,Plan!$B$5:$B$83,I26)/60 -> 16.916667
I27: Requisitos | J27: =SUMIFS(Plan!$J$5:$J$83,Plan!$B$5:$B$83,I27)/60 -> 12.5
I28: Estrategia | J28: =SUMIFS(Plan!$J$5:$J$83,Plan!$B$5:$B$83,I28)/60 -> 10.25
I29: Planificación | J29: =SUMIFS(Plan!$J$5:$J$83,Plan!$B$5:$B$83,I29)/60 -> 7.6666667
I30: Diseño | J30: =SUMIFS(Plan!$J$5:$J$83,Plan!$B$5:$B$83,I30)/60 -> 5.5
I31: Implementación | J31: =SUMIFS(Plan!$J$5:$J$83,Plan!$B$5:$B$83,I31)/60 -> 56.333333
I32: Pruebas | J32: =SUMIFS(Plan!$J$5:$J$83,Plan!$B$5:$B$83,I32)/60 -> 18.333333
I33: Retrospectiva | J33: =SUMIFS(Plan!$J$5:$J$83,Plan!$B$5:$B$83,I33)/60 -> 8.6666667
I35: Total | J35: =SUM(J26:J33) -> 136.16667

Sheet Horas Reales
I6: Carga de horas reales por rol/semana
J8: Total | K8: 1 | L8: 2 | M8: 3 | N8: 4 | O8: 5 | P8: 6 | Q8: 7 | R8: 8 | S8: 9
